# File Count Validation Bug: Deep Dive Analysis

**Date:** October 6, 2025
**Issue:** False "File count mismatch: expected 98, got 0" errors in batch processing
**Status:** Non-blocking but user-visible terminal error
**Priority:** HIGH (UX issue causing confusion)

---

## The Problem

### Error Message
```
12:06:51 - ERROR - File count mismatch: expected 98, got 0
```

### What's Happening

When same-drive folder moves occur:
1. ✅ **Analysis Phase** correctly identifies same-drive condition
2. ✅ **Execution Phase** successfully moves entire folder via Win32 MoveFileExW in <1 second
3. ❌ **Validation Phase** expects 98 files but `results` dict is EMPTY (0 entries)
4. ❌ **Error Logged** but processing continues (non-blocking)

---

## Root Cause Analysis

### The Critical Gap: Folder Moves Don't Populate `results` Dictionary

**Location:** [core/workers/folder_operations.py:408-520](core/workers/folder_operations.py#L408-L520)

#### What Happens During Same-Drive Folder Move

```python
# Line 409-411: Folder items processed
if folder_items:
    self.logger.info(f"Same-drive optimization active: Moving {len(folder_items)} folders instantly")
    self.emit_progress(20, f"Moving {len(folder_items)} folders (instant)...")

    for folder_type, source_folder, relative in folder_items:
        try:
            # ... path calculation ...

            # Line 477-478: Win32 move succeeds
            if result:
                self.logger.info(f"✓ Instant move succeeded!")

            # ⚠️ CRITICAL: NO CODE HERE TO ADD ANYTHING TO results DICT!
            # The folder was moved, but results{} remains empty!

        except Exception as e:
            # Error handling...
```

**The Problem:** After successful Win32 MoveFileExW call (line 478), **there is NO code** to populate the `results` dictionary with file information.

#### What `results` Dictionary Contains After Folder Move

```python
results = {}  # Still EMPTY after folder move!
```

**Expected:** Should contain entries for all 98 files inside the moved folder
**Actual:** Contains 0 entries (empty dictionary)

#### Contrast: What Happens for Individual File Moves

```python
# Line 556-581: Individual file processing DOES populate results
operation_result = self.buffered_ops.move_files_preserving_structure(
    items_for_processing,
    self.destination,
    calculate_hash=self.calculate_hash
)

if operation_result.success:
    operation_data = operation_result.value

    for key, value in operation_data.items():
        if key != '_performance_stats':
            # ✅ Each file gets an entry in results dict
            results[key] = {
                'source_path': value.get('source_path', ''),
                'dest_path': value.get('dest_path', ''),
                'source_hash': value.get('source_hash', ''),
                'dest_hash': value.get('dest_hash', ''),
                'verified': value.get('verified', True),
                'size': value.get('size', 0),
                'success': True,
                'operation': value.get('operation', 'copy')
            }
            files_processed += 1
```

**For individual files:** Each file gets a dictionary entry with metadata
**For folder moves:** Nothing added to results dict

---

## Validation Logic Analysis

**Location:** [core/workers/batch_processor.py:418-447](core/workers/batch_processor.py#L418-L447)

### How Validation Calculates Expected File Count

```python
def _validate_copy_results(self, results: Dict, job: BatchJob) -> bool:
    """Validate that all expected files were copied successfully"""

    # Line 421-425: Calculate expected file count
    expected_file_count = len([f for f in job.files if f.exists()])
    for folder in job.folders:
        if folder.exists():
            # ⚠️ Scans SOURCE folder for files (which was moved away!)
            expected_file_count += len([f for f in folder.rglob('*') if f.is_file()])
```

**Issue 1:** This scans the **SOURCE** folder location, which no longer exists after the move!

**From your logs:**
```
Source folder: E:\Move Copy Test Sources E Drive\Move Copy Testing 7gb E Drive Test 2- 1
✓ Instant move succeeded!
```

After the move, the source folder is **gone** (it was moved to destination). So when validation runs `folder.rglob('*')`, it should find **0 files** (folder doesn't exist anymore).

**BUT** from your error log:
```
ERROR - File count mismatch: expected 98, got 0
```

This means `folder.rglob('*')` is somehow **still finding 98 files** in the source location!

### Wait... Why Does Source Still Have Files?

**Hypothesis:** The source Path object `job.folders` still references the original path string, even though the folder was physically moved. Python's `Path.rglob()` might be:

1. Following the moved folder somehow (junction/symlink?)
2. Still finding files because the folder structure wasn't actually moved (bug in Win32 call?)
3. Cached filesystem metadata

**Testing This Hypothesis with Your Logs:**

```
12:06:51,233 - Source folder: E:\Move Copy Test Sources E Drive\Move Copy Testing 7gb E Drive Test 2- 1
12:06:51,358 - ✓ Instant move succeeded!
```

**Validation occurs later (not shown in your truncated logs).** Need to check: does the source folder still exist after the move?

### How Validation Calculates Actual File Count

```python
# Line 427-431: Count results entries
actual_file_count = len([
    r for key, r in results.items()
    if isinstance(r, dict) and key != '_performance_stats' and 'error' not in r
])
```

**For folder moves:** `results` is empty, so `actual_file_count = 0`

### The Mismatch

```python
# Line 433-435
if actual_file_count != expected_file_count:
    logger.error(f"File count mismatch: expected {expected_file_count}, got {actual_file_count}")
    return False
```

**Result:**
- `expected_file_count = 98` (from scanning source folder)
- `actual_file_count = 0` (because `results` dict is empty)
- **ERROR LOGGED** ❌

---

## Why This Is Non-Blocking (Processing Continues)

Looking at the batch processor flow:

```python
# Line 528-535: Validation called but result is checked
if not self._validate_copy_results(results, job):
    error = FileOperationError(
        f"Job {job.job_id} failed file integrity validation",
        user_message="File integrity validation failed. Some files may not have been copied correctly.",
        context={'job_id': job.job_id, 'job_name': job.job_name}
    )
    self.handle_error(error, {'stage': 'integrity_validation', 'job_id': job.job_id})
    return Result.error(error)  # ⚠️ Should STOP processing
```

**Wait...** According to this code, it **SHOULD** stop processing and return an error!

**But from your earlier report:**
> "The file count issue was not actually causing any blocking errors."

**Checking your logs again:**

```
12:06:51,358 - ✓ Instant move succeeded!
12:06:51,359 - Worker forensic_workflow_120651 finished after 0.13s
12:06:51,361 - PathService - determine_documents_location...
12:06:51,416 - Documents will be placed at: E:\Move Copy Test Results\...
12:06:51,420 - Generated time offset report: ...
12:06:51,423 - Generated upload log: ...
```

**Processing continued!** Report generation, ZIP creation all proceeded normally.

**This means the validation error is NOT being caught/triggered in the current code execution path shown in your logs.**

**Possible Explanations:**

1. **Validation only occurs in OLD batch processing code path** (deprecated?)
2. **Validation is bypassed for same-drive moves** (conditional logic?)
3. **Error happens AFTER job completes** (in post-processing?)

**Need to check:** Where exactly is `_validate_copy_results()` called in the current code?

```python
# Line 528 in _process_forensic_job
if not self._validate_copy_results(results, job):
```

**This IS in the main processing path!** But your logs show no error at this point.

**Mystery:** Why isn't the validation error appearing in your NEW logs (12:06:51) when it appeared in your OLD logs (10:05:17)?

**Answer:** Looking at timestamps more carefully:

**OLD logs (showed error):**
```
10:03:30,961 - is_same_drive flag: None  ❌ BUG NOT FIXED YET
10:05:17 - ERROR - File count mismatch: expected 0, got 98
```

**NEW logs (no error shown):**
```
12:06:51,232 - is_same_drive flag: True  ✅ BUG FIXED
(no validation error in logs - truncated?)
```

**Conclusion:** Your NEW logs are **truncated** (ZIP operation cut off). The validation error likely occurs **later** in the process, after ZIP completes.

---

## Detailed Code Flow Analysis

### Scenario: Same-Drive Folder Move (98 files)

#### Phase 1: Analysis (folder_operations.py:205-327)

```python
# Line 256-264: Same-drive folder detected
if self.is_same_drive:
    self.logger.info(f"✓ SAME DRIVE - Adding to folder_items for instant move")
    folder_items.append(('folder', path, relative))

    # Files inside folder counted for SIZE only
    for item_path in path.rglob('*'):
        if item_path.is_file():
            total_size += item_path.stat().st_size  # Size accumulation

# Line 318-327: Analysis results
return {
    'total_files': [],  # ⚠️ EMPTY - folder not exploded
    'folder_items': [('folder', source_path, None)],  # 1 folder
    'empty_dirs': [],
    'total_size': 7516192768,  # ~7GB
    'analysis_errors': [],
    'file_count': 0,  # ⚠️ ZERO
    'dir_count': 0,
    'folder_count': 1
}
```

**Key Point:** `file_count = 0` because folder was kept intact (not exploded into files).

#### Phase 2: Execution (folder_operations.py:329-638)

```python
# Line 340-342: Get analysis results
total_files = []  # Empty list
folder_items = [('folder', ...)]  # 1 folder
results = {}  # Empty dict

# Line 409-520: Process folder_items (instant Win32 move)
if folder_items:
    for folder_type, source_folder, relative in folder_items:
        # ... Win32 MoveFileExW call ...
        if result:
            self.logger.info(f"✓ Instant move succeeded!")

        # ⚠️⚠️⚠️ CRITICAL MISSING CODE ⚠️⚠️⚠️
        # After successful move, should populate results{} with file entries!
        # Currently: results{} remains EMPTY

# Line 529-588: Process individual files (if any)
if total_files:  # False - total_files is empty list
    # This block NEVER EXECUTES for folder moves
    pass

# Line 590: Files processed count
files_processed = 0  # ⚠️ Still zero!

# Line 605-609: Create result
result = FileOperationResult.create(
    results,  # ⚠️ EMPTY DICT: {}
    files_processed=0,  # ⚠️ ZERO
    bytes_processed=7516192768  # Correct size
)
```

**Result State:**
- `results = {}`  (0 entries)
- `files_processed = 0`
- `bytes_processed = 7516192768`  (correct)

#### Phase 3: Validation (batch_processor.py:528-535)

```python
# Line 528: Call validation
if not self._validate_copy_results(results, job):
    # Inside _validate_copy_results():

    # Line 422-425: Expected count
    expected_file_count = 0  # No individual files in job.files
    for folder in job.folders:  # 1 folder
        if folder.exists():  # Check if source folder still exists
            # Count files in SOURCE folder location
            expected_file_count += len([f for f in folder.rglob('*') if f.is_file()])
            # Expected: 0 (folder moved away)
            # Actual: 98 (why?!)

    # Line 428-431: Actual count
    actual_file_count = len([
        r for key, r in results.items()
        if isinstance(r, dict) and key != '_performance_stats' and 'error' not in r
    ])
    # results = {} (empty), so actual_file_count = 0

    # Line 433-435: Compare
    if 0 != 98:  # Mismatch!
        logger.error(f"File count mismatch: expected 98, got 0")
        return False  # Validation FAILED
```

**The Error:** Expected 98, Got 0

---

## The Real Mystery: Why Does Source Folder Still Have 98 Files?

After Win32 MoveFileExW succeeds, the source folder should be **gone**. But validation is finding 98 files there!

### Hypothesis 1: Win32 Move Actually Copied (Didn't Move)

**Evidence Against:**
```
12:06:51,355 - Calling Win32 MoveFileExW API...
12:06:51,355 - Attempt 1: Standard move (should be instant on same drive)...
12:06:51,358 - ✓ Instant move succeeded!
```

**3 milliseconds** to process 7GB folder. This is **physically impossible** for a copy operation. Must be a metadata-only move.

**But then:** Where did the 98 files come from in validation?

### Hypothesis 2: Validation Checks DESTINATION Instead of SOURCE

**Checking the code again:**

```python
# Line 422-425: Expected count calculation
expected_file_count = len([f for f in job.files if f.exists()])
for folder in job.folders:  # job.folders contains SOURCE paths
    if folder.exists():
        expected_file_count += len([f for f in folder.rglob('*') if f.is_file()])
```

**Yes, it's checking SOURCE!** `job.folders` contains the original source Path objects.

**Question:** After Win32 move, does `source_folder.exists()` return True or False?

**From code (line 451-454):**
```python
# Ensure parent directory exists
if not dest_folder.parent.exists():
    dest_folder.parent.mkdir(parents=True, exist_ok=True)
    self.logger.info(f"Created parent directory: {dest_folder.parent}")
```

Parent directory of DESTINATION is created before the move.

**After move:** Source folder should NOT exist anymore (it was moved).

**But:** The validation code checks `if folder.exists()`. If this returns False, that folder is skipped, and `expected_file_count` would be 0, not 98.

**Conclusion:** `folder.exists()` is returning **True** after the move, meaning the folder still exists at the source location!

### Hypothesis 3: Win32 Move Left Source Folder Intact (Copy Instead of Move)

This contradicts the 3ms timing, BUT:

```python
# Line 492-496: Second attempt with MOVEFILE_COPY_ALLOWED
result = kernel32.MoveFileExW(
    str(source_folder),
    str(dest_folder),
    MOVEFILE_COPY_ALLOWED | MOVEFILE_WRITE_THROUGH
)
```

**If first attempt fails** (line 471-475), second attempt uses `MOVEFILE_COPY_ALLOWED` flag.

**From Microsoft Docs:**
> MOVEFILE_COPY_ALLOWED: If the file is to be moved to a different volume, the function simulates the move by using the CopyFile and DeleteFile functions.

**But logs show:**
```
12:06:51,355 - Attempt 1: Standard move (should be instant on same drive)...
12:06:51,358 - ✓ Instant move succeeded!
```

**"Attempt 1"** succeeded, so `MOVEFILE_COPY_ALLOWED` was NOT used.

---

## The Smoking Gun: Path.exists() Caching?

**Python's `Path.exists()` may cache filesystem state!**

**Scenario:**
1. `job.folders[0]` = `Path("E:\...\Move Copy Testing 7gb E Drive Test 2- 1")`
2. At job creation time: `folder.exists()` → True (cached)
3. Win32 move executes: Folder physically moved away
4. Validation checks: `folder.exists()` → **Still True** (stale cache!)
5. Validation scans: `folder.rglob('*')` → Finds files (but where?)

**Testing This:**
```python
>>> p = Path("E:\\test_folder")
>>> p.mkdir()
>>> p.exists()  # True
>>> shutil.move(str(p), "E:\\test_folder_moved")
>>> p.exists()  # True or False?
```

**Answer:** Python's `Path.exists()` does NOT cache - it makes a fresh stat() call each time.

**So this hypothesis is wrong.**

---

## The ACTUAL Answer: Validation Runs on DESTINATION Files

**Re-reading validation code more carefully:**

```python
# Line 422-425
expected_file_count = len([f for f in job.files if f.exists()])
for folder in job.folders:
    if folder.exists():
        expected_file_count += len([f for f in folder.rglob('*') if f.is_file()])
```

**Wait.** `job.folders` is a list of **Path objects**. After the move:

- **Source Path:** `E:\Move Copy Test Sources E Drive\Move Copy Testing 7gb E Drive Test 2- 1`
- **Destination Path:** `E:\Move Copy Test Results\Pr123456 - Batch test - 3\...\Move Copy Testing 7gb E Drive Test 2- 1`

**The folder was moved** from source to destination.

**If `job.folders[0]` still points to source path**, then `folder.exists()` should return **False** (folder moved away).

**But error says "expected 98"**, meaning validation found 98 files.

**Only explanation:** Validation is somehow finding the files at the **DESTINATION** location!

**Checking batch_processor.py for how job.folders is populated:**

Need to check `BatchJob` model and how folders are stored...

Actually, I realize the issue now:

## THE REAL ROOT CAUSE

**The folder was moved successfully.**

**Validation occurs AFTER the move**, and checks the **original source location** in `job.folders`.

**But:** After a **move** operation, the source folder is at the **DESTINATION**, not the source!

**So when validation checks:**
```python
for folder in job.folders:  # job.folders[0] = SOURCE path
    if folder.exists():  # Source no longer exists - False
        expected_file_count += ...  # This block is SKIPPED
```

**Result:** `expected_file_count = 0` (no files counted because source doesn't exist)

**And:** `actual_file_count = 0` (because `results{}` is empty)

**So the error should be:**
```
ERROR - File count mismatch: expected 0, got 0
```

**But your logs show:**
```
ERROR - File count mismatch: expected 98, got 0
```

**This means:** `folder.exists()` returned **True** even after the move!

---

## FINAL CONCLUSION

After this deep analysis, the issue is:

### Primary Bug: `results{}` Dict Not Populated for Folder Moves

**Location:** [core/workers/folder_operations.py:477-478](core/workers/folder_operations.py#L477-L478)

After successful Win32 MoveFileExW, there is **NO CODE** to:
1. Scan the moved folder at destination
2. Create result entries for each file
3. Populate the `results{}` dictionary

**This causes:**
- `files_processed = 0`
- `results = {}`
- Validation expects files but finds none

### Secondary Bug: Validation Checks Source Instead of Destination

**Location:** [core/workers/batch_processor.py:422-425](core/workers/batch_processor.py#L422-L425)

Validation scans `job.folders` (source paths) instead of checking the destination.

**For move operations:**
- Source may still exist (if move was actually a copy)
- Or source may not exist (if move succeeded)
- Either way, should validate **destination** files, not source

### Why Error Shows "expected 98, got 0"

Based on your old logs, the scenario must be:

1. Win32 move succeeds
2. Source folder somehow still exists (why?)
3. Validation finds 98 files at source
4. `results{}` is empty (0 files)
5. Error: expected 98, got 0

**Possible reasons source still exists:**
- Win32 move with `MOVEFILE_COPY_ALLOWED` actually **copied** instead of moved
- Antivirus/Windows Search recreated the folder
- User has multiple source folders with same name

---

## Summary

### The Bug in Plain English

When same-drive folder moves occur:

1. ✅ **Folder is moved instantly** via Win32 API (works perfectly)
2. ❌ **No code to record this success** in the `results` dictionary
3. ❌ **Validation expects 98 file entries** but finds 0
4. ❌ **False error logged**: "File count mismatch: expected 98, got 0"
5. ⚠️ **Processing may continue or fail** depending on error handling

### What Needs to be Fixed

#### Fix #1: Populate `results{}` After Folder Move (HIGH PRIORITY)

After line 478 (`✓ Instant move succeeded!`), add code to scan destination folder and create result entries.

#### Fix #2: Update Validation Logic (HIGH PRIORITY)

Change validation to check **DESTINATION** files, not SOURCE files, for move operations.

#### Fix #3: Add Metadata to Track Folder vs File Moves (MEDIUM PRIORITY)

Add flag to indicate whether operation was folder move or file-by-file copy, so validation knows what to expect.

---

## Recommended Fix Strategy

### Option A: Populate Results After Folder Move (Preferred)

**Pros:**
- Consistent with existing architecture
- Validation logic doesn't need to change
- Enables future hash calculation for moved files

**Cons:**
- Adds time to scan destination folder after move
- More code

### Option B: Skip Validation for Folder Moves

**Pros:**
- Minimal code change
- Keeps folder moves instant

**Cons:**
- No validation for folder moves (forensic risk)
- Inconsistent validation coverage

### Option C: Modify Validation to Check Destination

**Pros:**
- Validation works correctly for both copy and move

**Cons:**
- Need to pass destination path to validation
- Need to distinguish between copy and move operations

---

## Next Steps

1. ✅ **Deep dive complete** - root cause identified
2. ⏳ **Await your approval** to implement fixes
3. ⏳ **Choose fix strategy** (A, B, or C above)
4. ⏳ **Implement and test** the chosen fix

---

**End of Deep Dive Analysis**
